Traceback (most recent call last):
  File "/home/ssilvera/Escritorio/Proyectos/Modelo_pagos/.venv/lib/python3.12/site-packages/jupyter_cache/executors/utils.py", line 58, in single_nb_execution
    executenb(
  File "/home/ssilvera/Escritorio/Proyectos/Modelo_pagos/.venv/lib/python3.12/site-packages/nbclient/client.py", line 1319, in execute
    return NotebookClient(nb=nb, resources=resources, km=km, **kwargs).execute()
           ^^^^^^^^^^^^^^^^^^^^^^^^^^^^^^^^^^^^^^^^^^^^^^^^^^^^^^^^^^^^^^^^^^^^^
  File "/home/ssilvera/Escritorio/Proyectos/Modelo_pagos/.venv/lib/python3.12/site-packages/jupyter_core/utils/__init__.py", line 165, in wrapped
    return loop.run_until_complete(inner)
           ^^^^^^^^^^^^^^^^^^^^^^^^^^^^^^
  File "/usr/lib/python3.12/asyncio/base_events.py", line 687, in run_until_complete
    return future.result()
           ^^^^^^^^^^^^^^^
  File "/home/ssilvera/Escritorio/Proyectos/Modelo_pagos/.venv/lib/python3.12/site-packages/nbclient/client.py", line 709, in async_execute
    await self.async_execute_cell(
  File "/home/ssilvera/Escritorio/Proyectos/Modelo_pagos/.venv/lib/python3.12/site-packages/nbclient/client.py", line 1062, in async_execute_cell
    await self._check_raise_for_error(cell, cell_index, exec_reply)
  File "/home/ssilvera/Escritorio/Proyectos/Modelo_pagos/.venv/lib/python3.12/site-packages/nbclient/client.py", line 918, in _check_raise_for_error
    raise CellExecutionError.from_cell_and_msg(cell, exec_reply_content)
nbclient.exceptions.CellExecutionError: An error occurred while executing the following cell:
------------------
import pandas as pd
pd.options.display.float_format = '{:.2f}'.format
from reporte_metricas import cargar_reportes

df = cargar_reportes("./Metrics/Train_Metrics.csv")

df_filtrado = df[df["Clase"].isin(["macro avg"])].sort_values(by="f1-score", ascending=False).reset_index(drop=True)
display(df_filtrado)

------------------

----- stdout -----
âš  No hay reportes guardados aÃºn.
------------------

[0;31m---------------------------------------------------------------------------[0m
[0;31mTypeError[0m                                 Traceback (most recent call last)
Cell [0;32mIn[1], line 7[0m
[1;32m      3[0m [38;5;28;01mfrom[39;00m[38;5;250m [39m[38;5;21;01mreporte_metricas[39;00m[38;5;250m [39m[38;5;28;01mimport[39;00m cargar_reportes
[1;32m      5[0m df [38;5;241m=[39m cargar_reportes([38;5;124m"[39m[38;5;124m./Metrics/Train_Metrics.csv[39m[38;5;124m"[39m)
[0;32m----> 7[0m df_filtrado [38;5;241m=[39m df[[43mdf[49m[43m[[49m[38;5;124;43m"[39;49m[38;5;124;43mClase[39;49m[38;5;124;43m"[39;49m[43m][49m[38;5;241m.[39misin([[38;5;124m"[39m[38;5;124mmacro avg[39m[38;5;124m"[39m])][38;5;241m.[39msort_values(by[38;5;241m=[39m[38;5;124m"[39m[38;5;124mf1-score[39m[38;5;124m"[39m, ascending[38;5;241m=[39m[38;5;28;01mFalse[39;00m)[38;5;241m.[39mreset_index(drop[38;5;241m=[39m[38;5;28;01mTrue[39;00m)
[1;32m      8[0m display(df_filtrado)

[0;31mTypeError[0m: 'NoneType' object is not subscriptable

