Traceback (most recent call last):
  File "/home/ssilvera/Escritorio/Proyectos/Modelo_pagos/.venv/lib/python3.12/site-packages/nbclient/client.py", line 782, in _async_poll_for_reply
    msg = await ensure_async(self.kc.shell_channel.get_msg(timeout=new_timeout))
          ^^^^^^^^^^^^^^^^^^^^^^^^^^^^^^^^^^^^^^^^^^^^^^^^^^^^^^^^^^^^^^^^^^^^^^
  File "/home/ssilvera/Escritorio/Proyectos/Modelo_pagos/.venv/lib/python3.12/site-packages/jupyter_core/utils/__init__.py", line 198, in ensure_async
    result = await obj
             ^^^^^^^^^
  File "/home/ssilvera/Escritorio/Proyectos/Modelo_pagos/.venv/lib/python3.12/site-packages/jupyter_client/channels.py", line 313, in get_msg
    raise Empty
_queue.Empty

During handling of the above exception, another exception occurred:

Traceback (most recent call last):
  File "/home/ssilvera/Escritorio/Proyectos/Modelo_pagos/.venv/lib/python3.12/site-packages/jupyter_cache/executors/utils.py", line 58, in single_nb_execution
    executenb(
  File "/home/ssilvera/Escritorio/Proyectos/Modelo_pagos/.venv/lib/python3.12/site-packages/nbclient/client.py", line 1319, in execute
    return NotebookClient(nb=nb, resources=resources, km=km, **kwargs).execute()
           ^^^^^^^^^^^^^^^^^^^^^^^^^^^^^^^^^^^^^^^^^^^^^^^^^^^^^^^^^^^^^^^^^^^^^
  File "/home/ssilvera/Escritorio/Proyectos/Modelo_pagos/.venv/lib/python3.12/site-packages/jupyter_core/utils/__init__.py", line 165, in wrapped
    return loop.run_until_complete(inner)
           ^^^^^^^^^^^^^^^^^^^^^^^^^^^^^^
  File "/usr/lib/python3.12/asyncio/base_events.py", line 687, in run_until_complete
    return future.result()
           ^^^^^^^^^^^^^^^
  File "/home/ssilvera/Escritorio/Proyectos/Modelo_pagos/.venv/lib/python3.12/site-packages/nbclient/client.py", line 709, in async_execute
    await self.async_execute_cell(
  File "/home/ssilvera/Escritorio/Proyectos/Modelo_pagos/.venv/lib/python3.12/site-packages/nbclient/client.py", line 1005, in async_execute_cell
    exec_reply = await self.task_poll_for_reply
                 ^^^^^^^^^^^^^^^^^^^^^^^^^^^^^^
  File "/home/ssilvera/Escritorio/Proyectos/Modelo_pagos/.venv/lib/python3.12/site-packages/nbclient/client.py", line 806, in _async_poll_for_reply
    error_on_timeout_execute_reply = await self._async_handle_timeout(timeout, cell)
                                     ^^^^^^^^^^^^^^^^^^^^^^^^^^^^^^^^^^^^^^^^^^^^^^^
  File "/home/ssilvera/Escritorio/Proyectos/Modelo_pagos/.venv/lib/python3.12/site-packages/nbclient/client.py", line 856, in _async_handle_timeout
    raise CellTimeoutError.error_from_timeout_and_cell(
nbclient.exceptions.CellTimeoutError: A cell timed out while it was being executed, after 30 seconds.
The message was: Cell execution timed out.
Here is a preview of the cell contents:
-------------------
['# Entrenar el modelo final con los mejores par√°metros', 'final_model = TabNetClassifier(**best_params, optimizer_fn=torch.optim.Adam, verbose=1)', 'final_model.fit(', '    X_train.values, y_train.values,', '    eval_set=[(X_val.values, y_val.values)],']
...
['conf_matrix_val = confusion_matrix(y_val, y_val_pred)', 'disp_val = ConfusionMatrixDisplay(conf_matrix_val, display_labels=np.unique(y))', 'disp_val.plot(cmap="Blues", values_format="d")', 'plt.title("Confusion Matrix (Validation Set)")', 'plt.show()']
-------------------

